Workbook

Sheet Cost of Debt
C1: 2020 | D1: 2021 | E1: 2022 | F1: 2023 | G1: 2024 | H1: 2025
B2: Cash | C2: 122609102 | D2: 344294926 | E2: 226411891 | F2: 169562958 | G2: 225776005 | H2: 291772464
B3: ST investment | C3: 41853971 | D3: 45243385 | E3: 47646350 | F3: 39949230 | G3: 70885229 | H3: 475695690
B4: Total Liquid asset | C4: =C2+C3 -> 164463073 | D4: =D2+D3 -> 389538311 | E4: =E2+E3 -> 274058241 | F4: =F2+F3 -> 209512188 | G4: =G2+G3 -> 296661234 | H4: =H2+H3 -> 767468154
B5: ST Debt | C5: 145729 | D5: 104 | E5: 947579 | F5: 554910475 | G5: 9877428 | H5: 0
B6: LT Debt | C6: 326089784 | D6: 326089784 | E6: 326089784 | F6: 526089784 | G6: 326089784 | H6: 326089784
B7: Total debt | C7: =C5+C6 -> 326235513 | D7: =D5+D6 -> 326089888 | E7: =E5+E6 -> 327037363 | F7: =F5+F6 -> 1081000259 | G7: =G5+G6 -> 335967212 | H7: =H5+H6 -> 326089784
B8: Net Debt | C8: =C4-C7 -> -161772440 | D8: =D4-D7 -> 63448423 | E8: =E4-E7 -> -52979122 | F8: =F4-F7 -> -871488071 | G8: =G4-G7 -> -39305978 | H8: =H4-H7 -> 441378370 | I8: (Total Liquid Asset-Total Debt)
B9: Interest Income | C9: 0 | D9: 0 | E9: 0 | F9: 0 | G9: 0 | H9: 0 | I9: Because it is an FMGG company not any Financing company
B10: Interest Expense | C10: 6823594 | D10: 4175940 | E10: 2086344 | F10: 41689500 | G10: 27200991 | H10: 4923815
B11: Net Interest | C11: =C10-C9 -> 6823594 | D11: =D10-D9 -> 4175940 | E11: =E10-E9 -> 2086344 | F11: =F10-F9 -> 41689500 | G11: =G10-G9 -> 27200991 | H11: =H10-H9 -> 4923815
B12: Implied cost of debt | D12: =D11/AVERAGE(C8:D8) -> -0.084942421 | E12: =E11/AVERAGE(D8:E8) -> 0.39856414 | F12: =F11/AVERAGE(E8:F8) -> -0.09019141 | G12: =G11/AVERAGE(F8:G8) -> -0.059730278 | H12: =H11/AVERAGE(G8:H8) -> 0.024492181 | I12: (Net Interest/average of net debt begin and end)
B14: Interest rate earned | D14: =D9/AVERAGE(SUM(D2:D3),SUM(C2:C3)) -> 0 | E14: =E9/AVERAGE(SUM(E2:E3),SUM(D2:D3)) -> 0 | F14: =F9/AVERAGE(SUM(F2:F3),SUM(E2:E3)) -> 0 | G14: =G9/AVERAGE(SUM(G2:G3),SUM(F2:F3)) -> 0 | H14: =H9/AVERAGE(SUM(H2:H3),SUM(G2:G3)) -> 0
B15: Interest rate paid | D15: =D10/AVERAGE(SUM(D5:D6),SUM(C5:C6)) -> 0.012803242 | E15: =E10/AVERAGE(SUM(E5:E6),SUM(D5:D6)) -> 0.0063887826 | F15: =F10/AVERAGE(SUM(F5:F6),SUM(E5:E6)) -> 0.059216457 | G15: =G10/AVERAGE(SUM(G5:G6),SUM(F5:F6)) -> 0.038393247 | H15: =H10/AVERAGE(SUM(H5:H6),SUM(G5:G6)) -> 0.014874293
B25: Cash | C25: 291772464
B26: ST investment | C26: 475695690
B27: Total Liquid asset | C27: =C25+C26 -> 767468154
B28: ST Debt | C28: 0
B29: LT Debt | C29: 326089784
B30: Total debt | C30: 326089784
B31: Net Debt | C31: 441378370
B32: Interest Income | C32: 0
B33: Interest Expense | C33: 4923815
B34: Net Interest | C34: 4923815
B35: Implied cost of debt | C35: 0.0245

Sheet Cost of Equity
A2: Current Share Price | B2: 533.1 | E2: Year | F2: 2020 | G2: 2021 | H2: 2022 | I2: 2023 | J2: 2024 | K2: 2025
A3: Current Dividend, Divo | B3: =AVERAGE(F3:K3) -> 4.0833333 | C3: (Avg cash dps, 2020-2025) | E3: Cash DPS (Tk/share) | F3: 3.5 | G3: 3.5 | H3: 2 | I3: 4 | J3: 5 | K3: 6.5
A4: Growth Rate,g | B4: =(K3/F3)^(1/5)-1 -> 0.13179837
A5: Cost of Equity, ke | B5: =B3*(1+B4)/B2+B4 -> 0.14046749
A7: Shares Outstanding (Current) | B7: 40780000
A8: Market Value of Equity, E | B8: =B7*B2 -> 21739818000
A9: Net Debt, D | B9: 441378370
A10: Total Value, V=E+D | B10: =B8+B9 -> 22181196370
A11: Cost of Debt (pre-tax), Kd | B11: 0.0245
A12: Tax Rate, T | B12: =-'Kohinoor Income Statement'!B13/'Kohinoor Income Statement'!B12 -> 0.27687864
A14: WACC | B14: =(B8/B10)*B5+(B9/B10)*B11*(1-B12) -> 0.1380249
A17: Cost of Debt | B17: 0.0245
A18: Cost of Equity | B18: 0.14046749
A19: Debt | B19: 441378370
A20: Equity | B20: 21739818000
A21: Market Value | B21: 22181196370
A22: Tax Rate | B22: 0.27687864
A23: WACC | B23: =(B20/B21)*B18+(B19/B21)*B17*(1-B22) -> 0.1380249

Sheet Tax
A1: Year | B1: 2025 | C1: 2024 | D1: 2023 | E1: 2022 | F1: 2021 | G1: 2020
A2: Profit Before Tax | B2: 874014118 | C2: 705061358 | D2: 525496568 | E2: 400024313 | F2: 297639224 | G2: 223641118
A3: Income Tax Expenses | B3: -241995841 | C3: -195529781 | D3: -148232252 | E3: -83259956 | F3: -63634885 | G3: -55677757
A4: Tax Rate | B4: =-B3/B2 -> 0.27687864 | C4: =-C3/C2 -> 0.27732307 | D4: =-D3/D2 -> 0.28208034 | E4: =-E3/E2 -> 0.20813724 | F4: =-F3/F2 -> 0.21379872 | G4: =-G3/G2 -> 0.24896029 | H4: (Tax Expenses/Profit Before Tax)

Sheet FCF
B1: 2025 | C1: 2024 | D1: 2023 | E1: 2022 | F1: 2021 | G1: 2020
A2: Net Operating Earnings | B2: 632018276 | C2: 509531576 | D2: 377264315 | E2: 316764356 | F2: 234004338 | G2: 167963362
A3: Changes in Operating Assets & Liabibilities: | J3: Accounts Receivable | K3: 60328048 | L3: 24557812 | M3: 19668530 | N3: 10536756 | O3: 6666809 | P3: 10079100
A4: Add Decrease in Accounts Receivable | B4: -35770236 | C4: -4889282 | D4: -9131774 | E4: -3869947 | F4: 3412291 | G4: - | J4: Inventories | K4: 1483829848 | L4: 1226269073 | M4: 1619031606 | N4: 1190511271 | O4: 1002898067 | P4: 916560031
A5: Subtract Increase in Inventories | B5: -257560775 | C5: 392762533 | D5: -428520335 | E5: -187613204 | F5: -86338036 | G5: - | J5: Creditors and Other Payables | K5: 555741022 | L5: 477106143 | M5: 408584873 | N5: 407648978 | O5: 466289982 | P5: 396324904
A6: Add increase in accounts payable | B6: 78634879 | C6: 68521270 | D6: 935895 | E6: -58641004 | F6: 69965078 | G6: - | J6: Accrued Expenses | N6: 575847511 | O6: 414097360 | P6: 216173985
A7: Accrued Expenses | B7: - | C7: - | D7: - | E7: 161750151 | F7: 197923375 | G7: -
A8: Net cash provided by Operating Activites | B8: 417322144 | C8: 965926097 | D8: -59451899 | E8: 228390352 | F8: 418967046 | G8: 167963362
A10: Proceeds from disposal of fixed Assets | B10: 1415000 | C10: 513500
A11: Acquisition of Property, Plant and Equipment | B11: -49593307 | C11: -10873117 | D11: -16126527 | E11: -14154986 | F11: -23264755 | G11: -9574426
A12: Disposal of Property, Plant and Equipment | E12: 485500 | G12: 584999
A13: Dividend Received | B13: 14493414 | C13: 12884426 | D13: 14419413 | E13: 16055254 | F13: 5663484 | G13: 3792496
A14: Fixed Deposit Receipts(FDR) | B14: -404810461 | C14: -30935999 | D14: 7697120 | E14: -2402964 | F14: -3389415 | G14: -9971724
A15: Investment in marketable securitirs | B15: 6671734 | C15: -394043 | D15: -50447650 | E15: -352176653 | F15: -99999653 | G15: 996
A16: Gain on sale of Marketable Securities | B16: -15397707 | C16: 360751 | D16: 49560830 | E16: 50178622
A17: Intercompany current account | G17: 3689602
A18: Interest received | B18: 45723087 | C18: 5553123 | D18: 5995232 | E18: 7471532
A19: Net Cash Used in Investing Activities | B19: -401498240 | C19: -22891359 | D19: 11098418 | E19: -294543695 | F19: -120990339 | G19: -11478057
A20: Free cash Flow before Interest Adjusment | B20: 15823904 | C20: 943034738 | D20: -48353481 | E20: -66153343 | F20: 297976707 | G20: 156485305
A21: Add back after-tax | B21: 241995841 | C21: 195529781 | D21: 148232252 | E21: 83259956 | F21: 63634885 | G21: 55677757
A22: Addback Interest | B22: 4923815 | C22: 27200991 | D22: 41689500 | E22: 2086344 | F22: 4175940 | G22: 6823594
A23: Free cash Flow before Interest Adjusment | B23: 262743560 | C23: 1165765510 | D23: 141568271 | E23: 19192957 | F23: 365787532 | G23: 218986656

Sheet CFFA Calc
C7: Net working capital
C8: Year | D8: Current Assets | E8: Current Liabilities | F8: NWC
C10: 2021 | D10: 2235994122 | E10: 932811501 | F10: =D10-E10 -> 1303182621
C11: 2022 | D11: 2601158096 | E11: 1032378483 | F11: =D11-E11 -> 1568779613
C12: 2023 | D12: 3120755373 | E12: 1019618503 | F12: =D12-E12 -> 2101136870
C13: 2024 | D13: 2677152985 | E13: 564791512 | F13: =D13-E13 -> 2112361473
C14: 2025 | D14: 3118807154 | E14: 654103935 | F14: =D14-E14 -> 2464703219
C15: Net Capital Spending
C16: Year | D16: Acquisition of PP&E | E16: Proceeds and disposal | F16: NCS
C18: 2021 | D18: 23264755 | E18: 0 | F18: =D18-E18 -> 23264755
C19: 2022 | D19: 14154986 | E19: 485500 | F19: =D19-E19 -> 13669486
C20: 2023 | D20: 16126527 | E20: 0 | F20: =D20-E20 -> 16126527
C21: 2024 | D21: 10873117 | E21: 513500 | F21: =D21-E21 -> 10359617
C22: 2025 | D22: 49593307 | E22: 1415000 | F22: =D22-E22 -> 48178307
C23: CFFA = OCF − NCS − ΔNWC
C24: Year | D24: OCF | E24: NCS | F24: NWC | G24: ΔNWC | H24: CFFA
F25: 1062970460
C26: 2021 | D26: 418967046 | E26: 23264755 | F26: 1303182621 | G26: =F26-F25 -> 240212161 | H26: =D26-E26-G26 -> 155490130
C27: 2022 | D27: 228390352 | E27: 13669486 | F27: 1568779613 | G27: =F27-F26 -> 265596992 | H27: =D27-E27-G27 -> -50876126
C28: 2023 | D28: -59451899 | E28: 16126527 | F28: 2101136870 | G28: =F28-F27 -> 532357257 | H28: =D28-E28-G28 -> -607935683
C29: 2024 | D29: 965926097 | E29: 10359617 | F29: 2112361473 | G29: =F29-F28 -> 11224603 | H29: =D29-E29-G29 -> 944341877
C30: 2025 | D30: 417322144 | E30: 48178307 | F30: 2464703219 | G30: =F30-F29 -> 352341746 | H30: =D30-E30-G30 -> 16802091
D35: Valuation of Kohinoor (FCF Model)
D36: Year | E36: FCF
D37: 2025 | E37: 262743560
D38: Perpetual growth rate | E38: 0.04
D39: WACC | E39: =0.138024896225991*100 -> 13.80249
D40: Growth | E40: =0.131798365631002*100 -> 13.179837
D41: FCF Value (years 1–5): = Base FCF × (1+Growth)^n | G41: Terminal value | H41: =F47*1.04/(0.138-0.04) -> 5.178307e+09 | J41: FOR NPV
D42: # of year | E42: Year | F42: FCF Value | G42: Total FCF | J42: # of year | K42: Year | L42: Discount factor | M42: Present Value
D43: 1 | E43: 2026 | F43: =E37*(1+0.1318)^1 -> 2.9737316e+08 | G43: 2.9737316e+08 | J43: 1 | K43: 2026 | L43: 0.8787 | M43: =F43*L43 -> 2.613018e+08
D44: 2 | E44: 2027 | F44: =E37*(1+0.1318)^2 -> 3.3656694e+08 | G44: 3.3656694e+08 | J44: 2 | K44: 2027 | L44: 0.7721 | M44: =F44*L44 -> 2.5986334e+08
D45: 3 | E45: 2028 | F45: =E37*(1+0.1318)^3 -> 3.8092647e+08 | G45: 3.8092647e+08 | J45: 3 | K45: 2028 | L45: 0.6785 | M45: =F45*L45 -> 2.5845861e+08
D46: 4 | E46: 2029 | F46: =E37*(1+0.1318)^4 -> 4.3113258e+08 | G46: 4.3113258e+08 | J46: 4 | K46: 2029 | L46: 0.5962 | M46: =F46*L46 -> 2.5704124e+08
D47: 5 | E47: 2030 | F47: =E37*(1+0.1318)^5 -> 4.8795585e+08 | G47: =H41+F47 -> 5.6662628e+09 | J47: 5 | K47: 2030 | L47: 0.5239 | M47: =G47*L47 -> 2.9685551e+09
D48: Terminal Value at year 5- 5666262816 | J48: Discount factor- 1/(1.1380)ⁿ | L48: NPV- | M48: =SUM(M43:M47) -> 4.0052201e+09
D49: NPV- | E49: 4.0052201e+09
D50: Equity Value | E50: =E49+('Cost of Debt'!H2+'Cost of Debt'!H3-'Cost of Debt'!H7) -> 4.4465984e+09
D51: No. Of shares- | E51: 40780000
D52: Stock price- | E52: =E50/E51 -> 109.03871
...

Sheet FCFF and FCFE calc
A1: For the year 2025 (LATEST)
A2: CFO
B3: 417322144
A4: Finance Cost (Interest)
B5: 4923815
A6: Tax Rate
B7: 0.27687864
A8: Acquisition of PP&E
B9: 49593307
A10: Proceeds from disposal
B11: 1415000
A12: NCS
B13: =B9-B11 -> 48178307
A14: Total debt 2025
B15: ='Kohinoor Balance Sheet'!B18+'Kohinoor Balance Sheet'!B23 -> 326089784
A16: Total debt 2024
B17: ='Kohinoor Balance Sheet'!C18+'Kohinoor Balance Sheet'!C23 -> 335967212
A18: Net borrowing
B19: =B15-B17 -> -9877428
D21: FCFF = | E21: CFO + Interest × (1 − Tax Rate) − Net Capital Spending (NCS)
E22: =B3+B5*(1-B7)-B13 -> 3.7270435e+08
D23: FCFE = | E23: CFO − NCS + Net Borrowing
E24: =E22-B5*(1-B7)+B19 -> 359266409
B32: Valuation of Kohinoor (FCFF Model) | R32: Valuation of Kohinoor (FCFE Model)
B33: Year | C33: FCFF | R33: Year | S33: FCFE
B34: 2025 | C34: 3.7270435e+08 | R34: 2025 | S34: 359266409
B35: Perpetual growth rate | C35: 0.04 | R35: Perpetual growth rate | S35: 0.04
B36: WACC | C36: =0.138024896225991*100 -> 13.80249 | R36: Cost of equity | S36: 0.1405
B37: Growth | C37: =0.131798365631002*100 -> 13.179837 | R37: Growth | S37: =0.131798365631002*100 -> 13.179837
B38: FCF Value (years 1–5): = Base FCF × (1+Growth)^n | E38: Terminal value | F38: =D44*1.04/(0.138-0.04) -> 7.3454799e+09 | K38: FOR NPV | R38: FCF Value (years 1–5): = Base FCF × (1+Growth)^n | U38: Terminal value | V38: =T44*1.04/(0.138-0.04) -> 7.0806369e+09 | Y38: FOR NPV
B39: # of year | C39: Year | D39: FCFF Value | E39: Total FCFF | K39: # of year | L39: Year | M39: Discount factor | N39: Present Value | R39: # of year | S39: Year | T39: FCFF Value | U39: Total FCFF | Y39: # of year | Z39: Year | AA39: Discount factor | AB39: Present Value
B40: 1 | C40: 2026 | D40: 421826177 | E40: 2.9737316e+08 | K40: 1 | L40: 2026 | M40: 0.8787 | N40: =D40*M40 -> 3.7065866e+08 | R40: 1 | S40: 2026 | T40: =S34*(1+0.1317)^1 -> 4.065818e+08 | U40: 2.9737316e+08 | Y40: 1 | Z40: 2026 | AA40: =1/(1+0.1405)^Y40 -> 0.87680842 | AB40: =T40*AA40 -> 3.5649434e+08
B41: 2 | C41: 2027 | D41: =C34*(1+0.1318)^2 -> 4.7742356e+08 | E41: 3.3656694e+08 | K41: 2 | L41: 2027 | M41: 0.7721 | N41: =D41*M41 -> 3.6861873e+08 | R41: 2 | S41: 2027 | T41: =S34*(1+0.1318)^2 -> 4.6020994e+08 | U41: 3.3656694e+08 | Y41: 2 | Z41: 2027 | AA41: =1/(1+0.1405)^Y41 -> 0.768793 | AB41: =T41*AA41 -> 3.5380618e+08
B42: 3 | C42: 2028 | D42: =C34*(1+0.1318)^3 -> 5.4034798e+08 | E42: 3.8092647e+08 | K42: 3 | L42: 2028 | M42: 0.6785 | N42: =D42*M42 -> 3.6662611e+08 | R42: 3 | S42: 2028 | T42: =S34*(1+0.1318)^3 -> 5.2086561e+08 | U42: 3.8092647e+08 | Y42: 3 | Z42: 2028 | AA42: =1/(1+0.1405)^Y42 -> 0.67408417 | AB42: =T42*AA42 -> 3.5110726e+08
B43: 4 | C43: 2029 | D43: =C34*(1+0.1318)^4 -> 6.1156585e+08 | E43: 4.3113258e+08 | K43: 4 | L43: 2029 | M43: 0.5962 | N43: =D43*M43 -> 3.6461556e+08 | R43: 4 | S43: 2029 | T43: =S34*(1+0.1318)^4 -> 5.8951569e+08 | U43: 4.3113258e+08 | Y43: 4 | Z43: 2029 | AA43: =1/(1+0.1405)^Y43 -> 0.59104268 | AB43: =T43*AA43 -> 3.4842893e+08
B44: 5 | C44: 2030 | D44: =C34*(1+0.1318)^5 -> 6.9217022e+08 | E44: =F38+D44 -> 8.0376502e+09 | K44: 5 | L44: 2030 | M44: 0.5239 | N44: =E44*M44 -> 4.2109249e+09 | R44: 5 | S44: 2030 | T44: =S34*(1+0.1318)^5 -> 6.6721386e+08 | U44: =V38+T44 -> 7.7478508e+09 | Y44: 5 | Z44: 2030 | AA44: =1/(1+0.1405)^Y44 -> 0.5182312 | AB44: =U44*AA44 -> 4.015178e+09
B45: Terminal Value at year 5- 7345479931 | K45: Discount factor- 1/(1.1380)ⁿ | M45: NPV- | N45: =SUM(N40:N44) -> 5.681444e+09 | R45: Terminal Value at year 5- 7718450199 | Y45: Discount factor- 1/(1.1405)ⁿ | AA45: NPV- | AB45: =SUM(AB40:AB44) -> 5.4250147e+09
B46: NPV- | C46: 5.681444e+09 | R46: NPV- | S46: 5.4250147e+09
B47: Equity Value | C47: =C46+('Cost of Debt'!H2+'Cost of Debt'!H3-'Cost of Debt'!H7) -> 6.1228223e+09 | R47: Equity Value | S47: 5.4250147e+09
B48: No. Of shares- | C48: 40780000 | R48: No. Of shares- | S48: 40780000
...

Sheet DDM Valuation 
A1: DDM Gordon Model Valuation
A3: 2025 | H3: Perpetual growth rate | I3: 0.04
A4: Net Profit | B4: ='Kohinoor Income Statement'!B16 -> 632018276 | H4: WACC | I4: ='Cost of Equity'!B14 -> 0.1380249
A5: Average Net Profit Growth | B5: =10.66/100 -> 0.1066 | H5: Growth | I5: ='Cost of Equity'!B4 -> 0.13179837
A6: Dividends | B6: ='Cost of Equity'!K3*'Cost of Equity'!B7 -> 265070000
A7: Dividends Growth Rate | B7: ='Cost of Equity'!B4 -> 0.13179837
A8: Total Shares | B8: ='Cost of Equity'!B7 -> 40780000
K9: DDM Gordon Model
D10: 1 | E10: 2 | F10: 3 | G10: 4 | H10: 5 | L10: 1 | M10: 2 | N10: 3 | O10: 4 | P10: 5
C11: Year | D11: 2026 | E11: 2027 | F11: 2028 | G11: 2029 | H11: 2030 | K11: Year | L11: 2026 | M11: 2027 | N11: 2028 | O11: 2029 | P11: 2030
C12: Net Profit | D12: =$B$4*(1+$B$5)^D10 -> 6.9939142e+08 | E12: =$B$4*(1+$B$5)^E10 -> 7.7394655e+08 | F12: =$B$4*(1+$B$5)^F10 -> 8.5644925e+08 | G12: =$B$4*(1+$B$5)^G10 -> 9.4774674e+08 | H12: =$B$4*(1+$B$5)^H10 -> 1.0487765e+09 | K12: Net Profit | L12: =D12 -> 6.9939142e+08 | M12: =E12 -> 7.7394655e+08 | N12: =F12 -> 8.5644925e+08 | O12: =G12 -> 9.4774674e+08 | P12: =H12 -> 1.0487765e+09
C13: Dividends | D13: =$B$6*(1+$B$7)^D10 -> 3.0000579e+08 | E13: =$B$6*(1+$B$7)^E10 -> 3.3954607e+08 | F13: =$B$6*(1+$B$7)^F10 -> 3.8429768e+08 | G13: =$B$6*(1+$B$7)^G10 -> 4.3494749e+08 | H13: =$B$6*(1+$B$7)^H10 -> 4.9227286e+08 | K13: Dividends | L13: =$B$6*(1+$B$7)^L10 -> 3.0000579e+08 | M13: =$B$6*(1+$B$7)^M10 -> 3.3954607e+08 | N13: =$B$6*(1+$B$7)^N10 -> 3.8429768e+08 | O13: =$B$6*(1+$B$7)^O10 -> 4.3494749e+08 | P13: =$B$6*(1+$B$7)^P10 -> 4.9227286e+08
C14: Shares | D14: =$B$8 -> 40780000 | E14: =$B$8 -> 40780000 | F14: =$B$8 -> 40780000 | G14: =$B$8 -> 40780000 | H14: =$B$8 -> 40780000 | K14: Shares | L14: =$B$8 -> 40780000 | M14: =$B$8 -> 40780000 | N14: =$B$8 -> 40780000 | O14: =$B$8 -> 40780000 | P14: =$B$8 -> 40780000
C15: Divid/Share | D15: =D13/D14 -> 7.3566894 | E15: =E13/E14 -> 8.326289 | F15: =F13/F14 -> 9.4236803 | G15: =G13/G14 -> 10.665706 | H15: =H13/H14 -> 12.071429 | K15: Years | L15: 1 | M15: 2 | N15: 3 | O15: 4 | P15: 5
C16: Terminal Value | H16: =H15/($I$4-$I$3) -> 123.14656 | K16: Divid/Share | L16: =D15 -> 7.3566894 | M16: =E15 -> 8.326289 | N16: =F15 -> 9.4236803 | O16: =G15 -> 10.665706 | P16: =H15 -> 12.071429
C17: CF | D17: =D15 -> 7.3566894 | E17: =E15 -> 8.326289 | F17: =F15 -> 9.4236803 | G17: =G15 -> 10.665706 | H17: =SUM(H15:H16) -> 135.21799 | K17: Terminal Value | P17: =H16 -> 123.14656
C18: PV | D18: =NPV(I4,D17:H17)*(1+I4)^0.5 -> 102.92939 | K18: CF | L18: =L16 -> 7.3566894 | M18: =M16 -> 8.326289 | N18: =N16 -> 9.4236803 | O18: =O16 -> 10.665706 | P18: =SUM(P16:P17) -> 135.21799
K19: Intrinsic Value
K20: =D18 -> 102.92939
K21: Market Price
K22: 533.1

Sheet PE Valuation
C3: Using PE MMM Valuation
C4: EPS | D4: ='Kohinoor Income Statement'!B17 -> 17.05 | E4: MKT Price | F4: ='DDM Valuation '!K22 -> 533.1
C5: Kohinoor P/E | D5: =F4/D4 -> 31.266862
C6: Industry P/E | D6: 62.09
D7: Intrinsic Value | F7: =D6*D4 -> 1058.6345

Sheet Du Pont
A1: Du Pont Analysis
A2: Year | B2: 2025 | C2: 2024 | D2: 2023 | E2: 2022 | F2: 2021 | G2: 2020
A3: Net Sales Revenue | B3: 6469741882 | C3: 5789042682 | D3: 5357546402 | E3: 4705164873 | F3: 4167164821 | G3: 3899549785
A4: Profit after Tax for the Period | B4: 632018276 | C4: 509531576 | D4: 377264315 | E4: 316764356 | F4: 234004338 | G4: 167963362
A5: TOTAL ASSETS | B5: 3432300280 | C5: 2961789149 | D5: 3418868778 | E5: 2907419574 | F5: 2542959283 | G5: 2021996287
A6: Total Shareholders' Equity | B6: 2415657269 | C6: 2033867841 | D6: 1821686825 | E6: 1493185638 | F6: 1233937716 | G6: 995804870
A8: Year | B8: 2025 | C8: 2024 | D8: 2023 | E8: 2022 | F8: 2021 | G8: 2020
A9: Net Profit Margin | B9: =B4/B3 -> 0.097688329 | C9: =C4/C3 -> 0.088016552 | D9: =D4/D3 -> 0.070417368 | E9: =E4/E3 -> 0.06732269 | F9: =F4/F3 -> 0.056154327 | G9: =G4/G3 -> 0.043072501
A10: Asset Turnover | B10: =B3/((B5+C5)/2) -> 2.0236632 | C10: =C3/((C5+D5)/2) -> 1.8145598 | D10: =D3/((D5+E5)/2) -> 1.6937408 | E10: =E3/((E5+F5)/2) -> 1.726546 | F10: =F3/((F5+G5)/2) -> 1.8257198 | G10: =G3/((G5+I6)/2) -> 3.8571285 | H10: Methodology differs from others due to lack of data
A11: Equity Multiplier | B11: =B5/B6 -> 1.4208557 | C11: =C5/C6 -> 1.4562348 | D11: =D5/D6 -> 1.8767599 | E11: =E5/E6 -> 1.9471253 | F11: =F5/F6 -> 2.060849 | G11: =G5/G6 -> 2.0305146
A13: Du Pont | B13: =B9*B10*B11 -> 0.28088651 | C13: =C9*C10*C11 -> 0.23257715 | D13: =D9*D10*D11 -> 0.22383884 | E13: =E9*E10*E11 -> 0.22632551 | F13: =F9*F10*F11 -> 0.2112825

Sheet Ratio
A1: Ratio | B1: 2025 | C1: 2024 | D1: 2023
A2: Asset Management & Asset Quality
A3: Total Asset Turnover | B3: 2.024 | C3: 1.815 | D3: 1.694
A4: Net Fixed Asset Turnover | B4: 21.633 | C4: 19.868 | D4: 17.729
A5: Equity Turnover | B5: 2.908 | C5: 3.003 | D5: 3.232
A6: Cash Flow & Capital Adequacy
A7: Operating Cash Flow to sales | B7: 0.0645 | C7: 0.1669 | D7: -0.0111
A8: Efficiency & Productivity & Capital Strength
A9: Inventory Turnover | B9: 3.426 | C9: 2.99 | D9: 2.968
A10: Inventory Processing Period (Days) | B10: 106.54 | C10: 122.06 | D10: 122.98
A11: Liquidity & Leverage
A12: Current Ratio | B12: 4.768 | C12: 4.74 | D12: 3.061
A13: Quick Ratio | B13: 2.5 | C13: 2.569 | D13: 1.473
A14: Cash Ratio | B14: 1.173 | C14: 0.525 | D14: 0.205
A15: Financial Leverage | B15: 1.421 | C15: 1.456 | D15: 1.877
A17: Profitability & Investment Return
A18: Gross Profit Margin | B18: 0.2825 | C18: 0.2651 | D18: 0.2218
A19: Operating Profit Margin | B19: 0.1356 | C19: 0.1289 | D19: 0.0976
A20: Net Profit Margin | B20: 0.0977 | C20: 0.088 | D20: 0.0704
A21: Return on Equity (ROE) | B21: 0.2841 | C21: 0.2643 | D21: 0.2276
A22: Return on Assets (ROA) | B22: 0.1977 | C22: 0.1597 | D22: 0.1193

Sheet Kohinoor Income Statement
A1: Particulars | B1: 2025 | C1: 2024 | D1: 2023 | E1: 2022 | F1: 2021 | G1: 2020
A2: Net Sales Revenue | B2: 6469741882 | C2: 5789042682 | D2: 5357546402 | E2: 4705164873 | F2: 4167164821 | G2: 3899549785
A3: Cost of Goods Sold | B3: 4642249673 | C3: 4254327924 | D3: 4169284256 | E3: 3793145401 | F3: 3364190911 | G3: 3171924005
A4: Gross Profit | B4: 1827492209 | C4: 1534714758 | D4: 1188262146 | E4: 912019472 | F4: 802973910 | G4: 727625780
A5: Administrative Expenses | B5: 128403926 | C5: 85034332 | D5: 80159444 | E5: 71538556 | F5: 71438205 | G5: 71452414
A6: Selling, Marketing and Distribution Expenses | B6: 821533640 | C6: 703282593 | D6: 585030886 | E6: 492793924 | F6: 429766888 | G6: 428036119
A7: Profit from Operations | B7: 877554643 | C7: 746397833 | D7: 523071816 | E7: 347686992 | F7: 301768817 | G7: 228137247
A8: Other Income | B8: 45083995 | C8: 21117583 | D8: 70389079 | E8: 74424880 | F8: 14928307 | G8: 13509520
A9: Finance Cost | B9: 4923815 | C9: 27200991 | D9: 41689500 | E9: 2086344 | F9: 4175940 | G9: 6823594
A10: Profit Before Contribution to WPPF & Welfare Funds | B10: 917714824 | C10: 740314426 | D10: 551771396 | E10: 420025529 | F10: 312521185 | G10: 234823174
A11: Contribution to WPPF & Welfare Funds | B11: 43700706 | C11: 35253068 | D11: 26274828 | E11: 20001216 | F11: 14881961 | G11: 11182056
A12: Profit Before Tax | B12: 874014118 | C12: 705061358 | D12: 525496568 | E12: 400024313 | F12: 297639224 | G12: 223641118
... A14: Current Tax | B14: -237032324 | C14: -197859554 | D14: -148232252 | E14: -83913325 | F14: -66958551 | G14: -56721718
A15: Deferred Tax Income/ (Expense) | B15: -4963517 | C15: 2329773 | E15: 653369 | F15: 3323666 | G15: 1043961
A16: Profit after Tax for the Period | B16: 632018276 | C16: 509531576 | D16: 377264315 | E16: 316764356 | F16: 234004338 | G16: 167963362 | I16: =(B16-C16)/C16 -> 0.24039079 | J16: =(C16-D16)/D16 -> 0.35059574 | K16: =(D16-E16)/E16 -> 0.19099358 | L16: =(E16-F16)/F16 -> 0.35366873 | M16: =(F16-G16)/G16 -> 0.3931868
A17: Earnings Per Share (EPS) | B17: 17.05 | C17: 13.74 | D17: 12.31 | E17: 9.17 | F17: 12.41 | G17: 8.32
I18: =AVERAGE(I16:M16) -> 0.30576713

Sheet Kohinoor Balance Sheet
A1: Particulars | B1: 2025 | C1: 2024 | D1: 2023 | E1: 2022 | F1: 2021 | G1: 2020
A2: Property, Plant and Equipment | B2: 308504545 | C2: 281669052 | D2: 292256338 | E2: 297895722 | F2: 304737290 | G2: 301717254
A3: Right of use assets | B3: 4988581 | C3: 2967112 | D3: 5857067 | E3: 8365756 | F3: 2227871 | G3: 3357370
A4: Total Non-Current Assets | B4: 313493126 | C4: 284636164 | D4: 298113405 | E4: 306261478 | F4: 306965161 | G4: 305074624
A5: Inventories | B5: 1483829848 | C5: 1226269073 | D5: 1619031606 | E5: 1190511271 | F5: 1002898067 | G5: 916560031
A6: Accounts Receivable | B6: 60328048 | C6: 24557812 | D6: 19668530 | E6: 10536756 | F6: 6666809 | G6: 10079100
A7: Loans, Advances and Deposits | B7: 343757971 | C7: 553169165 | D7: 502216479 | E7: 408726904 | F7: 494212536 | G7: 466215444
A8: Short Term Investment | B8: 475695690 | C8: 70885229 | D8: 39949230 | E8: 47646350 | F8: 45243385 | G8: 41853971
A9: Investment in shares and others | B9: 463423133 | C9: 576495701 | D9: 770326570 | E9: 717324924 | F9: 342678399 | G9: 159604015
A10: Cash and Cash Equivalents | B10: 291772464 | C10: 225776005 | D10: 169562958 | E10: 226411891 | F10: 344294926 | G10: 122609102
A11: Total Current Assets | B11: 3118807154 | C11: 2677152985 | D11: 3120755373 | E11: 2601158096 | F11: 2235994122 | G11: 1716921663
A12: TOTAL ASSETS | B12: 3432300280 | C12: 2961789149 | D12: 3418868778 | E12: 2907419574 | F12: 2542959283 | G12: 2021996287
... A22: Total Non-Current Liabilities | B22: 362539077 | C22: 363129797 | D22: 577563450 | E22: 381855520 | F22: 376210067 | G22: 372240214
A23: Short Term Borrowings/Finance | C23: 9877428 | D23: 554910475 | E23: 947579 | F23: 104 | G23: 145729
A24: Lease finance-current portion | B24: 2987828 | C24: 2135842 | D24: 2712006 | E24: 2431688 | F24: 1233575 | G24: 2538266
A25: Creditors and Other Payables | B25: 555741022 | C25: 477106143 | D25: 408584873 | E25: 407648978 | F25: 466289982 | G25: 396324904
A26: Accrued Expenses | E26: 575847511 | F26: 414097360 | G26: 216173985
A27: WPPF/Employee benefit obligation | B27: 31291937 | C27: 22228858 | D27: 14495776 | E27: 12136422 | F27: 25261288 | G27: 19295927
A28: Dividend Payable | B28: 64083148 | C28: 53443241 | D28: 38915373 | E28: 33366305 | F28: 25929192 | G28: 19472392
A29: Total Current Liabilities | B29: 654103935 | C29: 564791512 | D29: 1019618503 | E29: 1032378483 | F29: 932811501 | G29: 653951203
A30: TOTAL EQUITY AND LIABILITIES | B30: 3432300281 | C30: 2961789150 | D30: 3418868778 | E30: 2907419641 | F30: 2542959284 | G30: 2021996287
A31: Net Asset Value (NAV) | B31: 65.16 | C31: 54.86 | D31: 59.46 | E31: 58.49 | F31: 55.58 | G31: 49.34
A32: Restated Net Asset Value | F32: 48.33
